<?xml version="1.0" encoding="utf-8"?>
<!-- This URDF was automatically created by SolidWorks to URDF Exporter! Originally created by Stephen Brawner (brawner@gmail.com) 
     Commit Version: 1.6.0-4-g7f85cfe  Build Version: 1.6.7995.38578
     For more information, please see http://wiki.ros.org/sw_urdf_exporter -->
<robot name="taurus" xmlns:xacro="http://ros.org/wiki/xacro">
  
    <!-- Colors -->
    <material name="black">
        <color rgba="0.0 0.0 0.0 1.0"/>
    </material>

    <material name="white">
        <color rgba="1.0 1.0 1.0 1.0"/>
    </material>

    <material name="orange">
        <color rgba="${255/255} ${108/255} ${10/255} 1.0"/>
    </material>   

    <!-- Links -->
    <link name="base_footprint"/>

    <link name="base_link">
        <inertial>
            <origin xyz="0.00275879340251001 -0.000160323414407668 0.0158295592625537" rpy="0 0 0" />
            <mass value="0.113" />
            <inertia ixx="6.15132942894087E-05" ixy="3.37534300204353E-07" ixz="-2.95632504344648E-07" iyy="8.46822261559733E-05" iyz="-9.68630964462554E-08" izz="0.000143380666972569" />
        </inertial>

        <visual>
            <origin xyz="0 0 0" rpy="0 0 0" />
            <geometry>
            <mesh filename="package://taurus_description/meshes/base_link.STL" />
            </geometry>
            <material name="orange"/>
        </visual>

        <collision>
            <origin xyz="0 0 0" rpy="0 0 0" />
            <geometry>
                <mesh filename="package://taurus_description/meshes/base_link.STL" />
            </geometry>
        </collision>
    </link>

    <joint name="base_joint" type="fixed">
        <parent link="base_footprint"/>
        <child link="base_link"/>
        <origin xyz="0.0 0.0 0.007" rpy="0 0 0"/>
    </joint>

    <link name="wheel_left_link">
        <inertial>
            <origin xyz="-2.99096858125819E-05 0.000104405542786706 0.0106748994421485" rpy="0 0 0" />
            <mass value="0.0193884068569417" />
            <inertia ixx="2.0510194557915E-04" ixy="-1.38176554484537E-04" ixz="-1.25876332418469E-04" iyy="2.06467928427853E-04" iyz="5.48385935622177E-04" izz="2.44092899915579E-04" />
        </inertial>

        <visual>
            <origin xyz="0 0 0" rpy="0 0 0" />
            <geometry>
                <mesh filename="package://taurus_description/meshes/wheel_left_tire.STL" />
            </geometry>
            <material name="black" />
        </visual>

        <collision>
            <origin xyz="0 0 0" rpy="0 0 0" />
            <geometry>
                <cylinder length="0.018" radius="0.033"/>
            </geometry>
        </collision>
    </link>

    <joint name="wheel_left_joint" type="continuous">
        <origin xyz="-0.0043278 0.031199 0.0080157" rpy="-1.5708 0.0038917 -0.0016425" />
        <parent link="base_link" />
        <child link="wheel_left_link" />
        <axis xyz="0 0 1" />
    </joint>

    <link name="wheel_right_link">
        <inertial>
            <origin xyz="5.80889775016746E-05 -8.73721543165756E-05 -0.010674936298826" rpy="0 0 0" />
            <mass value="0.0193884068569417" />
            <inertia ixx="2.0551514945078E-04" ixy="-6.42512948553551E-04" ixz="-3.05250616726642E-4" iyy="2.06054394462654E-04" iyz="4.59129190656125E-04" izz="2.44093230009149E-04" />
        </inertial>

        <visual>
            <origin xyz="0 0 0" rpy="0 0 0" />
            <geometry>
                <mesh filename="package://taurus_description/meshes/wheel_right_tire.STL" />
            </geometry>
            <material name="black" />
        </visual>

        <collision>
            <origin xyz="0 0 0" rpy="0 0 0" />
            <geometry>
                <cylinder length="0.018" radius="0.033"/>
            </geometry>
        </collision>
    </link>

    <joint name="wheel_right_joint" type="continuous">
        <origin xyz="-0.0043053 -0.0312 0.008035" rpy="-1.5708 0 0.00018716" />
        <parent link="base_link" />
        <child link="wheel_right_link" />
        <axis xyz="0 0 1" />
    </joint>

    <link name="caster_ball_link">
        <inertial>
            <origin xyz="3.4694E-18 -6.9389E-18 0" rpy="0 0 0" />
            <mass value="0.00042116" />
            <inertia ixx="3.6426E-09" ixy="-7.0682E-27" ixz="0" iyy="3.6426E-09" iyz="1.1632E-25" izz="3.6426E-09" />
        </inertial>

        <visual>
            <origin xyz="0 0 0" rpy="0 0 0" />
            <geometry>
                <mesh filename="package://taurus_description/meshes/caster_ball.STL" />
            </geometry>
            <material name="white"/>
        </visual>

        <collision>
            <origin xyz="0 0 0" rpy="0 0 0" />
            <geometry>
                <sphere radius="0.005" />
            </geometry>
        </collision>
    </link>

    <joint name="caster_ball_joint" type="fixed">
        <origin xyz="0.056407 -3.7223E-05 -0.0016971" "-1.5862 0.02388 1.6283"/>
        <parent link="base_ball_link" />
        <child link="caster_ball_link" />
    </joint>

    <link name="scan_link">
        <inertial>
            <origin xyz="0.00088546 -0.00014004 0.010058" rpy="0 0 0" />
            <mass value="0.0055715" />
            <inertia ixx="2.359E-07" ixy="-6.4604E-10" ixz="-3.628E-08" iyy="6.474E-07" iyz="-3.2589E-09" izz="5.6499E-07" />
        </inertial>

        <visual>
            <origin xyz="0 0 0" rpy="0 0 0" />
            <geometry>
                <mesh filename="package://taurus_description/meshes/scan_link.STL" />
            </geometry>
            <material name="black"/>
        </visual>

        <collision>
            <origin xyz="0 0 0" rpy="0 0 0" />
            <geometry>
                <mesh filename="package://taurus_description/meshes/scan_link.STL" />
            </geometry>
        </collision>
    </link>

    <joint name="imu_joint" type="fixed">
        <parent link="base_link"/>
        <child link="imu_link"/>
        <origin xyz="0 0 0" rpy="0 0 0"/>
    </joint>

    <link name="imu_link"/>

</robot>